2018-09-04 09:42:44,321 utils.py[line:51]-[ERROR]: error in func: get_metrics, error msg: HTTPConnectionPool(host='indata-10-110-13-114.indata.com', port=60030): Max retries exceeded with url: /jmx (Caused by ConnectTimeoutError(<urllib3.connection.HTTPConnection object at 0x04683710>, 'Connection to indata-10-110-13-114.indata.com timed out. (connect timeout=5)'))
